<?xml version="1.0"?>
<robot xmlns:xacro="http://www.ros.org/wiki/xacro">

    <xacro:include filename="inertial_macros.xacro"/>
<!-- MATIREALS -->
    <material name="white">
        <color rgba="1 1 1 1"/>
    </material>

    <material name="orange">
        <color rgba="1 0.3 0.1 1"/>
    </material>

    <material name="blue">
        <color rgba="0.2 0.2 1 1"/>
    </material>

    <material name="black">
        <color rgba="0 0 0 1"/>
    </material>

<!-- BASE LINK -->
    <link name="base_link" >  
     </link>

        <!-- CHASSIS -->
    <link name="chassis">
        <visual>
            <geometry>
                <box size="0.4 0.3 0.15"/>
            </geometry>
            <origin xyz="0.2 0.0 0.075"/>
            <material name="white"/>
        </visual>
        <collision>
            <geometry>
                <box size="0.4 0.3 0.15"/>
            </geometry>
            <origin xyz="0.2 0.0 0.075"/>      
        </collision>
        <xacro:inertial_box mass="0.5" x="0.4" y="0.3" z="0.15">
            <origin xyz="0.02 0 0.075" rpy="0.0 0.0 0.0"/>
        </xacro:inertial_box>
    </link>

    <gazebo reference="chassis">
        <material>Gazebo/White</material>
    </gazebo>

    <joint name="chassi_link_joint" type="fixed">
        <parent link="base_link"/>
        <child link="chassis"/>
        <origin xyz="-0.1 0.0 0.0"/>        
    </joint>

        <!-- LEFT WHEEEL -->
    <link name="left_wheel">
        <visual>
        <geometry>
            <cylinder radius="0.05" length="0.04"/>
            </geometry>
            <material name="blue"/>
        </visual>
        <collision>
            <geometry>
                <cylinder radius="0.05" length="0.04"/>
            </geometry>
        </collision>
        <xacro:inertial_cylinder mass="0.1" length="0.04" radius="0.03">
            <origin xyz="0.0 0 0.0" rpy="0.0 0.0 0.0"/>
        </xacro:inertial_cylinder>
    </link>

    <gazebo reference="left_wheel">
        <material>Gazebo/Blue</material>
    </gazebo>

    <joint name="left_wheel_joint" type="continuous">
        <parent link="base_link"/>
        <child link="left_wheel"/>
        <origin xyz="0.0 0.175 0.0" rpy="-${pi/2} 0.0 0.0"/>
        <axis xyz="0.0 0.0 1"/>
    </joint>

        <!-- RIGHT WHEEL -->
    <link name="right_wheel">
        <visual>
            <geometry>
                <cylinder radius="0.05" length="0.04"/>
            </geometry>
            <material name="blue"/>
        </visual>
        <collision>
            <geometry>
                <cylinder radius="0.05" length="0.04"/>
            </geometry>            
        </collision>
        <xacro:inertial_cylinder mass="0.1" length="0.04" radius="0.03">
            <origin xyz="0.0 0 0.0" rpy="0.0 0.0 0.0"/>
        </xacro:inertial_cylinder>
    </link>
    <gazebo reference="right_wheel">
        <material>Gazebo/Blue</material>
    </gazebo>

    <joint name="right_wheel_joint" type="continuous">
        <parent link="base_link"/>
        <child link="right_wheel"/>
        <origin xyz="0.0 -0.175 0.0" rpy="${pi/2} 0.0 0.0"/>
        <axis xyz="0.0 0.0 -1"/>
    </joint>

    <!-- CASTER WHEEL LINK -->
    <link name="caster_wheel">
        <visual>
            <geometry>
                <sphere radius="0.025"/>
            </geometry>
            <material name="blue"/>
        </visual>
        <collision>
            <geometry>
                <sphere radius="0.025"/>
            </geometry>
            <material name="blue"/>
        </collision>
        <xacro:inertial_sphere mass="0.2" radius="0.025">
            <origin xyz="0.0 0 0.0" rpy="0.0 0.0 0.0"/>
        </xacro:inertial_sphere>
    </link>
    <gazebo reference="caster_wheel">
        <material>Gazebo/Blue</material>
        <mu1 value="0.001"/>
        <mu2 value="0.001"/>
    </gazebo>

    <joint name="caster_wheel_joint" type="fixed">
        <parent link="base_link"/>
        <child link="caster_wheel"/>
        <origin xyz="0.24 0.0 -0.025" rpy="0.0 0.0 0.0"/>
    </joint>
</robot>